Workbook

Sheet README
A1: Campari Group (BIT: CPR) — DCF & Trading Comparables Valuation Model
A2: Author: Maria Sfondrini · July 2026 · Academic portfolio project — not investment advice
A4: HOW TO READ THIS MODEL
A5: Blue font = hardcoded input you can change (assumptions, market data).
A6: Black font = formula. Never overwrite.
A7: Yellow fill = key assumption or figure to VERIFY against primary sources before presenting.
A9: TABS
A10: 1. Assumptions — every driver of the model, with rationale notes
A11: 2. DCF Model — historicals (FY2024-25A), 5-year forecast, FCFF, discounting, sensitivity
A12: 3. Comps — peer trading multiples and implied valuation
A13: 4. Football Field — valuation summary across methods
A15: PRIMARY SOURCES (figures pulled July 12, 2026)
... A29: · Read the FY2025 Annual Report and form YOUR view on revenue/margin assumptions — the model is the engine, the view is yours

Sheet Assumptions
A1: Assumptions — all blue cells are inputs
A3: FORECAST DRIVERS (FY2026E – FY2030E)
A4: Year | C4: 2026E | D4: 2027E | E4: 2028E | F4: 2029E | G4: 2030E
A5: Net sales growth (reported) | C5: 0.005 | D5: 0.03 | E5: 0.03 | F5: 0.028 | G5: 0.025 | H5: 2026 ~flat: +2.5% organic less ~€70m disposals & €30m tariffs (guidance); then GDP+ premium-spirits growth
A6: EBITDA-adjusted margin | C6: 0.26 | D6: 0.264 | E6: 0.267 | F6: 0.269 | G6: 0.27 | H6: 25.7% in FY2025A; gradual accretion from SG&A programme (200bps by 2027) partly reinvested
A7: D&A (% of net sales) | C7: 0.048 | D7: 0.048 | E7: 0.048 | F7: 0.048 | G7: 0.048 | H7: FY2025A: EBITDA−EBIT = €148m = 4.85% of sales; held flat
A8: Capex (% of net sales) | C8: 0.07 | D8: 0.06 | E8: 0.05 | F8: 0.045 | G8: 0.045 | H8: FY2025A 8.8% incl. €143m extraordinary; normalising as extraordinary programme ends
A9: Net working capital (% of net sales) | C9: 0.426 | H9: Actual Dec-25 operating WC €1,299.4m (inv. 1,686.9 + rec. 327.1 − pay. 714.6) / net sales — FY2025 press release
A10: Tax rate (on EBIT) | C10: 0.27 | H10: Approx. group effective rate — verify from Annual Report tax note
A12: WACC
A13: Risk-free rate (10Y Bund) | C13: 0.0301 | H13: 10Y Bund 3.01% — TradingEconomics, Jun 2026
A14: Equity risk premium | C14: 0.055 | H14: Damodaran mature-market ERP
A15: Levered beta: raw (col C) / Blume-adjusted (col D) | C15: 0.43 | D15: =0.67*C15+0.33 | H15: Raw 5Y beta 0.43 (stockanalysis.com, Jul 2026); Blume adjustment 0.67·raw+0.33 — standard mean-reversion
A16: Cost of equity | C16: =C13+D15*C14
A17: Pre-tax cost of debt | C17: 0.036 | H17: Approx. blended rate on bonds/loans — verify from Annual Report
A18: After-tax cost of debt | C18: =C17*(1-C10)
A19: Debt / (Debt + Equity), target | C19: 0.23 | H19: Current: ND €1,958m vs mcap €6,580m ≈ 23%
A20: WACC | C20: =(1-C19)*C16+C19*C18
A22: TERMINAL VALUE & MARKET DATA
A23: Terminal growth rate (g) | C23: 0.02 | H23: Long-run nominal growth ≤ eurozone nominal GDP
A24: Exit EV/EBITDA multiple | C24: 11.5 | H24: Around peer median — see Comps tab
A25: Net financial debt, FY2025A (€m) | C25: 1958 | H25: FY2025 press release
A26: Shares outstanding (m) | C26: 1199 | H26: Mcap €6.58bn / price €5.49 (stockanalysis.com, Jul 2, 2026); treasury shares 32.5m at Dec-25
A27: Current share price (€) | C27: 5.49 | H27: Close Jul 2, 2026 — refresh on the day you present

Sheet DCF Model
A1: DCF Model — FCFF (€m unless stated)
B3: 2024A | C3: 2025A | D3: 2026E | E3: 2027E | F3: 2028E | G3: 2029E | H3: 2030E
A4: Year index (forecast) | D4: 1 | E4: 2 | F4: 3 | G4: 4 | H4: 5
A5: OPERATING MODEL
A6: Net sales | B6: 3069.7 | C6: 3051 | D6: =C6*(1+Assumptions!C5) | E6: =D6*(1+Assumptions!D5) | F6: =E6*(1+Assumptions!E5) | G6: =F6*(1+Assumptions!F5) | H6: =G6*(1+Assumptions!G5)
A7: growth % | C7: =C6/B6-1 | D7: =D6/C6-1 | E7: =E6/D6-1 | F7: =F6/E6-1 | G7: =G6/F6-1 | H7: =H6/G6-1
A8: EBITDA-adjusted | C8: 785 | D8: =D6*Assumptions!C6 | E8: =E6*Assumptions!D6 | F8: =F6*Assumptions!E6 | G8: =G6*Assumptions!F6 | H8: =H6*Assumptions!G6
A9: margin % | C9: =IF(C8="","",C8/C6) | D9: =IF(D8="","",D8/D6) | E9: =IF(E8="","",E8/E6) | F9: =IF(F8="","",F8/F6) | G9: =IF(G8="","",G8/G6) | H9: =IF(H8="","",H8/H6)
A10: D&A | C10: =C8-C11 | D10: =D6*Assumptions!C7 | E10: =E6*Assumptions!D7 | F10: =F6*Assumptions!E7 | G10: =G6*Assumptions!F7 | H10: =H6*Assumptions!G7
A11: EBIT-adjusted | B11: 604.9 | C11: 637 | D11: =D8-D10 | E11: =E8-E10 | F11: =F8-F10 | G11: =G8-G10 | H11: =H8-H10
A13: FREE CASH FLOW TO FIRM (FORECAST)
A14: NOPAT (EBIT × (1 − tax)) | D14: =D11*(1-Assumptions!$C$10) | E14: =E11*(1-Assumptions!$C$10) | F14: =F11*(1-Assumptions!$C$10) | G14: =G11*(1-Assumptions!$C$10) | H14: =H11*(1-Assumptions!$C$10)
A15: (+) D&A | D15: =D10 | E15: =E10 | F15: =F10 | G15: =G10 | H15: =H10
A16: (−) Capex | D16: =-D6*Assumptions!C8 | E16: =-E6*Assumptions!D8 | F16: =-F6*Assumptions!E8 | G16: =-G6*Assumptions!F8 | H16: =-H6*Assumptions!G8
A17: Net working capital (level) | C17: =C6*Assumptions!$C$9 | D17: =D6*Assumptions!$C$9 | E17: =E6*Assumptions!$C$9 | F17: =F6*Assumptions!$C$9 | G17: =G6*Assumptions!$C$9 | H17: =H6*Assumptions!$C$9
A18: (−) Change in NWC | D18: =-(D17-C17) | E18: =-(E17-D17) | F18: =-(F17-E17) | G18: =-(G17-F17) | H18: =-(H17-G17)
A19: FCFF | D19: =D14+D15+D16+D18 | E19: =E14+E15+E16+E18 | F19: =F14+F15+F16+F18 | G19: =G14+G15+G16+G18 | H19: =H14+H15+H16+H18
A20: Discount factor | D20: =1/(1+Assumptions!$C$20)^D4 | E20: =1/(1+Assumptions!$C$20)^E4 | F20: =1/(1+Assumptions!$C$20)^F4 | G20: =1/(1+Assumptions!$C$20)^G4 | H20: =1/(1+Assumptions!$C$20)^H4
A21: PV of FCFF | D21: =D19*D20 | E21: =E19*E20 | F21: =F19*F20 | G21: =G19*G20 | H21: =H19*H20
A23: VALUATION — GORDON GROWTH
A24: Sum of PV of FCFF (2026-30) | B24: =SUM(D21:H21)
A25: Terminal value (Gordon) | B25: =H19*(1+Assumptions!C23)/(Assumptions!C20-Assumptions!C23)
A26: PV of terminal value | B26: =B25*H20
A27: Enterprise value | B27: =B24+B26
A28: (−) Net financial debt | B28: =-Assumptions!C25
A29: Equity value | B29: =B27+B28
A30: Implied share price (€) | B30: =B29/Assumptions!C26
A31: Upside / (downside) vs current | B31: =B30/Assumptions!C27-1
A32: % of EV in terminal value | B32: =B26/B27
A34: VALUATION — EXIT MULTIPLE
A35: Terminal value (exit EV/EBITDA) | B35: =H8*Assumptions!C24
A36: PV of terminal value | B36: =B35*H20
A37: Enterprise value | B37: =B24+B36
A38: Implied share price (€) | B38: =(B37-Assumptions!C25)/Assumptions!C26
A39: Upside / (downside) vs current | B39: =B38/Assumptions!C27-1
A41: SENSITIVITY — IMPLIED PRICE (GORDON): WACC × TERMINAL g
A42: WACC \ g | B42: 0.015 | C42: 0.0175 | D42: 0.02 | E42: 0.0225 | F42: 0.025
A43: 0.055 | B43: =($D$19/(1+$A43)^1+$E$19/(1+$A43)^2+$F$19/(1+$A43)^3+$G$19/(1+$A43)^4+$H$19/(1+$A43)^5+($H$19*(1+B$42)/($A43-B$42))/(1+$A43)^5-Assumptions!$C$25)/Assumptions!$C$26 | C43: =($D$19/(1+$A43)^1+$E$19/(1+$A43)^2+$F$19/(1+$A43)^3+$G$19/(1+$A43)^4+$H$19/(1+$A43)^5+($H$19*(1+C$42)/($A43-C$42))/(1+$A43)^5-Assumptions!$C$25)/Assumptions!$C$26 | D43: =($D$19/(1+$A43)^1+$E$19/(1+$A43)^2+$F$19/(1+$A43)^3+$G$19/(1+$A43)^4+$H$19/(1+$A43)^5+($H$19*(1+D$42)/($A43-D$42))/(1+$A43)^5-Assumptions!$C$25)/Assumptions!$C$26 | E43: =($D$19/(1+$A43)^1+$E$19/(1+$A43)^2+$F$19/(1+$A43)^3+$G$19/(1+$A43)^4+$H$19/(1+$A43)^5+($H$19*(1+E$42)/($A43-E$42))/(1+$A43)^5-Assumptions!$C$25)/Assumptions!$C$26 | F43: =($D$19/(1+$A43)^1+$E$19/(1+$A43)^2+$F$19/(1+$A43)^3+$G$19/(1+$A43)^4+$H$19/(1+$A43)^5+($H$19*(1+F$42)/($A43-F$42))/(1+$A43)^5-Assumptions!$C$25)/Assumptions!$C$26
A44: 0.06 | B44: =($D$19/(1+$A44)^1+$E$19/(1+$A44)^2+$F$19/(1+$A44)^3+$G$19/(1+$A44)^4+$H$19/(1+$A44)^5+($H$19*(1+B$42)/($A44-B$42))/(1+$A44)^5-Assumptions!$C$25)/Assumptions!$C$26 | C44: =($D$19/(1+$A44)^1+$E$19/(1+$A44)^2+$F$19/(1+$A44)^3+$G$19/(1+$A44)^4+$H$19/(1+$A44)^5+($H$19*(1+C$42)/($A44-C$42))/(1+$A44)^5-Assumptions!$C$25)/Assumptions!$C$26 | D44: =($D$19/(1+$A44)^1+$E$19/(1+$A44)^2+$F$19/(1+$A44)^3+$G$19/(1+$A44)^4+$H$19/(1+$A44)^5+($H$19*(1+D$42)/($A44-D$42))/(1+$A44)^5-Assumptions!$C$25)/Assumptions!$C$26 | E44: =($D$19/(1+$A44)^1+$E$19/(1+$A44)^2+$F$19/(1+$A44)^3+$G$19/(1+$A44)^4+$H$19/(1+$A44)^5+($H$19*(1+E$42)/($A44-E$42))/(1+$A44)^5-Assumptions!$C$25)/Assumptions!$C$26 | F44: =($D$19/(1+$A44)^1+$E$19/(1+$A44)^2+$F$19/(1+$A44)^3+$G$19/(1+$A44)^4+$H$19/(1+$A44)^5+($H$19*(1+F$42)/($A44-F$42))/(1+$A44)^5-Assumptions!$C$25)/Assumptions!$C$26
A45: 0.065 | B45: =($D$19/(1+$A45)^1+$E$19/(1+$A45)^2+$F$19/(1+$A45)^3+$G$19/(1+$A45)^4+$H$19/(1+$A45)^5+($H$19*(1+B$42)/($A45-B$42))/(1+$A45)^5-Assumptions!$C$25)/Assumptions!$C$26 | C45: =($D$19/(1+$A45)^1+$E$19/(1+$A45)^2+$F$19/(1+$A45)^3+$G$19/(1+$A45)^4+$H$19/(1+$A45)^5+($H$19*(1+C$42)/($A45-C$42))/(1+$A45)^5-Assumptions!$C$25)/Assumptions!$C$26 | D45: =($D$19/(1+$A45)^1+$E$19/(1+$A45)^2+$F$19/(1+$A45)^3+$G$19/(1+$A45)^4+$H$19/(1+$A45)^5+($H$19*(1+D$42)/($A45-D$42))/(1+$A45)^5-Assumptions!$C$25)/Assumptions!$C$26 | E45: =($D$19/(1+$A45)^1+$E$19/(1+$A45)^2+$F$19/(1+$A45)^3+$G$19/(1+$A45)^4+$H$19/(1+$A45)^5+($H$19*(1+E$42)/($A45-E$42))/(1+$A45)^5-Assumptions!$C$25)/Assumptions!$C$26 | F45: =($D$19/(1+$A45)^1+$E$19/(1+$A45)^2+$F$19/(1+$A45)^3+$G$19/(1+$A45)^4+$H$19/(1+$A45)^5+($H$19*(1+F$42)/($A45-F$42))/(1+$A45)^5-Assumptions!$C$25)/Assumptions!$C$26
...

Sheet Comps
A1: Trading Comparables — global premium spirits
A3: Company | B3: EV/EBITDA | C3: P/E (fwd) | F3: Source: stockanalysis.com, Jun-Jul 2026 — refresh before presenting
A4: Diageo | B4: 11.25 | C4: 12.79
A5: Pernod Ricard | B5: 9.43 | C5: 10.83
A6: Rémy Cointreau | B6: 14.17 | C6: 27.05
A7: Brown-Forman | B7: 12.08 | C7: 15.38
A8: Median | B8: =MEDIAN(B4:B7) | C8: =MEDIAN(C4:C7)
A9: Min | B9: =MIN(B4:B7)
A10: Max | B10: =MAX(B4:B7)
A12: IMPLIED CAMPARI VALUATION (ON FY2025A EBITDA-ADJ €785m)
A13: FY2025A EBITDA-adjusted (€m) | B13: ='DCF Model'!C8
A14: Implied EV @ median (€m) | B14: =B13*B8
A15: Implied equity value (€m) | B15: =B14-Assumptions!C25
A16: Implied share price @ median (€) | B16: =B15/Assumptions!C26
A17: Implied price @ min (€) | B17: =(B13*B9-Assumptions!C25)/Assumptions!C26
A18: Implied price @ max (€) | B18: =(B13*B10-Assumptions!C25)/Assumptions!C26
A20: Note: Campari has historically traded at a premium to Pernod/Diageo on growth and
A21: brand momentum (Aperol/Espolòn); discuss whether that premium is still justified.

Sheet Football Field
A1: Valuation Summary — implied share price ranges (€)
A3: Method | B3: Low | C3: High | D3: Midpoint
A4: DCF — Gordon (WACC 7.5%→5.5% @ g=2.0%) | B4: ='DCF Model'!D47 | C4: ='DCF Model'!D43 | D4: =(B4+C4)/2
A5: DCF — Exit multiple (±1.0x around input) | B5: =('DCF Model'!$B$24+('DCF Model'!$H$8*(Assumptions!$C$24-1))*'DCF Model'!$H$20-Assumptions!$C$25)/Assumptions!$C$26 | C5: =('DCF Model'!$B$24+('DCF Model'!$H$8*(Assumptions!$C$24+1))*'DCF Model'!$H$20-Assumptions!$C$25)/Assumptions!$C$26 | D5: =(B5+C5)/2
A6: Trading comps (min → max multiple) | B6: =Comps!B17 | C6: =Comps!B18 | D6: =(B6+C6)/2
A8: Current share price (€) | B8: =Assumptions!C27
A10: Reading: where the current price sits inside (or outside) these ranges is the story —
A11: write your recommendation (Buy / Hold / Sell + target) in the research note.
